Workbook

Sheet Completeness
A1: OUTLIER DETECTION
A3: colonna | B3: descrittore | C3: valutare? | D3: check
A4: price | B4: applica una strategia di outlier detection / dà direttamente gli outlier | C4: Sì | D4: 1
A5: bed | B5: applica una strategia di outlier detection / dà direttamente gli outlier | C5: Sì | D5: 1
A6: bath | B6: applica una strategia di outlier detection / dà direttamente gli outlier | C6: Sì | D6: 1
A7: acre_lot | B7: applica una strategia di outlier detection / dà direttamente gli outlier | C7: Sì | D7: 1
A8: house_size | B8: applica una strategia di outlier detection / dà direttamente gli outlier | C8: Sì | D8: 1
A11: Completeness parziale Outlier Detection: | B11: =SUM(D4:D8)/COUNTA(C4:C8) -> 1
A14: DATA STANDARDIZATION
A16: colonna | B16: descrittore | C16: valutare? | D16: check
A17: status | B17: propone una soluzione per i valori troncati alla prima lettera ('s' e 'f', dovrebbero essere 'sold' e 'for_sale') | C17: Sì | D17: 1
A18: price | B18: propone una soluzione per la presenza del simbolo '$' | C18: Sì | D18: 1
A19: bed | B19: propone una soluzione per la presenza di numeri rappresentati come parole in una colonna numerica | C19: Sì | D19: 1
A20: bath | B20: propone una soluzione per la presenza di numeri rappresentati come parole in una colonna numerica | C20: Sì | D20: 1
A21: street | B21: propone una soluzione per la presenza del numero civico alla fine o inizio dell'indirizzo | C21: Sì | D21: 0
A22: state | B22: propone una soluzione per la presenza di nomi di stati accorciati o allungati | C22: Sì | D22: 1
A23: house_size | B23: propone una soluzione per la mancanza di una unità di misura univoca | C23: Sì | D23: 1
A24: prev_sold_date | B24: propone una soluzione per la mancanza di un formato unico per le date | C24: Sì | D24: 1
A27: Completeness parziale Data Standardization: | B27: =SUM(D17:D24)/COUNTA(C17:C24) -> 0.875
A30: DATA IMPUTATION | B30: N.B. Quando si carica un csv in pandas le stringhe vuote vengono convertite in NaN
A32: colonna | B32: descrittore | C32: valutare? | D32: check
A33: brokered_by | B33: fa imputation dei NaN | C33: Sì | D33: 1
A34: brokered_by | B34: fa imputation dei -1 | C34: Sì | D34: 0
A35: brokered_by | B35: fa imputation delle stringhe vuote | C35: Sì | D35: 1
A36: status | B36: fa imputation degli 'Unknown' | C36: Sì | D36: 1
A37: status | B37: fa imputation dei '-' | C37: Sì | D37: 1
A38: status | B38: fa imputation delle stringhe vuote | C38: Sì | D38: 1
A39: price | B39: fa imputation dei NaN | C39: Sì | D39: 1
A40: price | B40: fa imputation dei -1 | C40: Sì | D40: 1
A41: price | B41: fa imputation delle stringhe vuote | C41: Sì | D41: 1
A42: bed | B42: fa imputation dei NaN | C42: Sì | D42: 1
A43: bed | B43: fa imputation dei -1 | C43: Sì | D43: 1
A44: bed | B44: fa imputation delle stringhe vuote | C44: Sì | D44: 1
... A68: prev_sold_date | B68: fa imputation delle stringhe vuote | C68: Sì | D68: 0
A71: Completeness parziale Data Imputation: | B71: =SUM(D33:D68)/COUNTA(C33:C68) -> 0.86111111
A74: DATA DEDUPLICATION
B76: descrittore | C76: valutare? | D76: check
B77: menziona o fa l'exact matching | C77: No | D77: 0
B78: menziona o fa il non-exact matching | C78: Sì | D78: 1
A81: Completeness parziale Data Deduplication: | B81: =SUM(D77:D78)/COUNTIF(C77:C78, "Sì") -> 1
...

Sheet Accuracy
A1: OUTLIER DETECTION
A3: colonna | B3: descrittore | C3: valutare? | D3: outlier corretti | E3: outlier sbagliati | F3: outlier mancanti | G3: Precision | H3: Recall | I3: F1-score | J3: dipendenza
A4: price | B4: outlier price | C4: =IF(Completeness!D4=1,"Sì","No") -> Sì | D4: 8 | E4: 2 | F4: 8 | G4: =IF(D4+E4=0, 0, D4/(D4+E4)) -> 0.8 | H4: =IF(D4+F4=0, 0, D4/(D4+F4)) -> 0.5 | I4: =IF(G4+H4=0, 0,(2*G4*H4)/(G4+H4)) -> 0.61538462 | J4: Completeness!B2
A5: bed | B5: outlier bed | C5: =IF(Completeness!D5=1,"Sì","No") -> Sì | D5: 9 | E5: 0 | F5: 0 | G5: =IF(D5+E5=0, 0, D5/(D5+E5)) -> 1 | H5: =IF(D5+F5=0, 0, D5/(D5+F5)) -> 1 | I5: =IF(G5+H5=0, 0,(2*G5*H5)/(G5+H5)) -> 1 | J5: Completeness!B3
A6: bath | B6: outlier bath | C6: =IF(Completeness!D6=1,"Sì","No") -> Sì | D6: 20 | E6: 0 | F6: 0 | G6: =IF(D6+E6=0, 0, D6/(D6+E6)) -> 1 | H6: =IF(D6+F6=0, 0, D6/(D6+F6)) -> 1 | I6: =IF(G6+H6=0, 0,(2*G6*H6)/(G6+H6)) -> 1 | J6: Completeness!B4
A7: acre_lot | B7: outlier acre_lot | C7: =IF(Completeness!D7=1,"Sì","No") -> Sì | D7: 11 | E7: 0 | F7: 0 | G7: =IF(D7+E7=0, 0, D7/(D7+E7)) -> 1 | H7: =IF(D7+F7=0, 0, D7/(D7+F7)) -> 1 | I7: =IF(G7+H7=0, 0,(2*G7*H7)/(G7+H7)) -> 1 | J7: Completeness!B5
A8: house_size | B8: outlier house_size | C8: =IF(Completeness!D8=1,"Sì","No") -> Sì | D8: 7 | E8: 0 | F8: 23 | G8: =IF(D8+E8=0, 0, D8/(D8+E8)) -> 1 | H8: =IF(D8+F8=0, 0, D8/(D8+F8)) -> 0.23333333 | I8: =IF(G8+H8=0, 0,(2*G8*H8)/(G8+H8)) -> 0.37837838 | J8: Completeness!B6
G9: =IFERROR(SUM(G4:G8)/COUNTIF(C4:C8, "Sì"), 0) -> 0.96 | H9: =IFERROR(SUM(H4:H8)/COUNTIF(C4:C8, "Sì"), 0) -> 0.74666667 | I9: =IFERROR(SUM(I4:I8)/COUNTIF(C4:C8, "Sì"), 0) -> 0.7987526
A12: Lista outliers
A13: price | B13: 13400.0, 20900.0, 24400.0, 26700.0, 27100.0, 635000.0, 699000.0, 699000.0, 725000.0, 725000.0, 749000.0, 888000.0, 999000.0, 999000.0, 1300000.0, 2365000.0
A14: bed | B14: 9, 9, 9, 10, 10, 11, 11, 11, 11
A15: bath | B15: 5, 5, 5, 6, 6, 6, 6, 7, 7, 8, 8, 8, 8, 8, 9, 10, 10, 10, 10, 10
A16: acre_lot | B16: 0.7, 0.83, 0.83, 1.07, 2.12, 10.0, 10.0, 14.25, 14.25, 27.59, 48.0
A17: house_size | B17: 7.7, 57.0, 58.0, 59.0, 60.0, 70.0, 89.0, 90.0, 110.0, 120.0, 140.0, 321.0, 321.0, 321.0, 3039.999999999114, 3057.0, 3351.999999999214, 3625.0, 3765.0, 3765.0, 4156.0, 4757.999999999432, 4757.999999999432, 4905.0, 6278.0, 8640.0, 9537.0, 9564.0, 9708.0, 9714.0
A20: Accuracy (F1) parziale Outlier Detection: | B20: =I9 -> 0.7987526 | C20: =IF(COUNTIF(C4:C8, "Sì")>0, "Sì", "No") -> Sì
A23: DATA STANDARDIZATION
A25: colonna | B25: descrittore | C25: valutare? | D25: check | E25: dipendenza
A26: status | B26: la soluzione proposta è valida | C26: =IF(Completeness!D17=1,"Sì","No") -> Sì | D26: 1 | E26: propone una soluzione per i valori troncati alla prima lettera ('s' e 'f', dovrebbero essere 'sold' e 'for_sale') (B17) | L26: =IF(MOD(ROW(), 2)=0, "Pari", "Dispari") -> Pari
A27: status | B27: la soluzione proposta è ottimale | C27: =IF(Completeness!D17=1,"Sì","No") -> Sì | D27: 1 | E27: propone una soluzione per i valori troncati alla prima lettera ('s' e 'f', dovrebbero essere 'sold' e 'for_sale') (B17) | L27: =IF(MOD(ROW(), 2)=0, "Pari", "Dispari") -> Dispari
A28: price | B28: la soluzione proposta è valida | C28: =IF(Completeness!D18=1,"Sì","No") -> Sì | D28: 1 | E28: propone una soluzione per la presenza del simbolo '$' (B18) | L28: =IF(MOD(ROW(), 2)=0, "Pari", "Dispari") -> Pari
A29: price | B29: la soluzione proposta è ottimale | C29: =IF(Completeness!D18=1,"Sì","No") -> Sì | D29: 1 | E29: propone una soluzione per la presenza del simbolo '$' (B18) | L29: =IF(MOD(ROW(), 2)=0, "Pari", "Dispari") -> Dispari
A30: bed | B30: la soluzione proposta è valida | C30: =IF(Completeness!D19=1,"Sì","No") -> Sì | D30: 1 | E30: propone una soluzione per la presenza di numeri rappresentati come parole in una colonna numerica (B19) | L30: =IF(MOD(ROW(), 2)=0, "Pari", "Dispari") -> Pari
A31: bed | B31: la soluzione proposta è ottimale | C31: =IF(Completeness!D19=1,"Sì","No") -> Sì | D31: 1 | E31: propone una soluzione per la presenza di numeri rappresentati come parole in una colonna numerica (B19) | L31: =IF(MOD(ROW(), 2)=0, "Pari", "Dispari") -> Dispari
A32: bath | B32: la soluzione proposta è valida | C32: =IF(Completeness!D20=1,"Sì","No") -> Sì | D32: 1 | E32: propone una soluzione per la presenza di numeri rappresentati come parole in una colonna numerica (B20) | L32: =IF(MOD(ROW(), 2)=0, "Pari", "Dispari") -> Pari
A33: bath | B33: la soluzione proposta è ottimale | C33: =IF(Completeness!D20=1,"Sì","No") -> Sì | D33: 1 | E33: propone una soluzione per la presenza di numeri rappresentati come parole in una colonna numerica (B20) | L33: =IF(MOD(ROW(), 2)=0, "Pari", "Dispari") -> Dispari
A34: street | B34: la soluzione proposta è valida | C34: =IF(Completeness!D21=1,"Sì","No") -> No | D34: 0 | E34: propone una soluzione per la presenza del numero civico alla fine o inizio dell'indirizzo (B21) | L34: =IF(MOD(ROW(), 2)=0, "Pari", "Dispari") -> Pari
A35: street | B35: la soluzione proposta è ottimale | C35: =IF(Completeness!D21=1,"Sì","No") -> No | D35: 0 | E35: propone una soluzione per la presenza del numero civico alla fine o inizio dell'indirizzo (B21) | L35: =IF(MOD(ROW(), 2)=0, "Pari", "Dispari") -> Dispari
A36: state | B36: la soluzione proposta è valida | C36: =IF(Completeness!D22=1,"Sì","No") -> Sì | D36: 1 | E36: propone una soluzione per la presenza di nomi di stati accorciati o allungati (B22) | L36: =IF(MOD(ROW(), 2)=0, "Pari", "Dispari") -> Pari
A37: state | B37: la soluzione proposta è ottimale | C37: =IF(Completeness!D22=1,"Sì","No") -> Sì | D37: 1 | E37: propone una soluzione per la presenza di nomi di stati accorciati o allungati (B22) | L37: =IF(MOD(ROW(), 2)=0, "Pari", "Dispari") -> Dispari
A38: house_size | B38: la soluzione proposta è valida | C38: =IF(Completeness!D23=1,"Sì","No") -> Sì | D38: 0 | E38: propone una soluzione per la mancanza di una unità di misura univoca (B23) | L38: =IF(MOD(ROW(), 2)=0, "Pari", "Dispari") -> Pari
A39: house_size | B39: la soluzione proposta è ottimale | C39: =IF(Completeness!D23=1,"Sì","No") -> Sì | D39: 0 | E39: propone una soluzione per la mancanza di una unità di misura univoca (B23) | L39: =IF(MOD(ROW(), 2)=0, "Pari", "Dispari") -> Dispari
A40: prev_sold_date | B40: la soluzione proposta è valida | C40: =IF(Completeness!D24=1,"Sì","No") -> Sì | D40: 1 | E40: propone una soluzione per la mancanza di un formato unico per le date (B24) | L40: =IF(MOD(ROW(), 2)=0, "Pari", "Dispari") -> Pari
A41: prev_sold_date | B41: la soluzione proposta è ottimale | C41: =IF(Completeness!D24=1,"Sì","No") -> Sì | D41: 1 | E41: propone una soluzione per la mancanza di un formato unico per le date (B24) | L41: =IF(MOD(ROW(), 2)=0, "Pari", "Dispari") -> Dispari
A44: Accuracy parziale Data Standardization: | B44: =IFERROR(( SUMIF(L26:L41, "Pari",D26:D41) * 0.8 + SUMIF(L26:L41, "Dispari",D26:D41) * 0.2)/(COUNTIF(C26:C41,"Sì")/2), 0) -> 0.85714286 | C44: =IF(COUNTIF(C26:C41, "Sì")>0, "Sì", "No") -> Sì
A47: DATA IMPUTATION
A49: colonna | B49: descrittore | C49: valutare? | D49: check | F49: Tecniche considerate ottimali
A50: brokered_by | B50: fa imputation dei NaN con una tecnica valida | C50: =IF(Completeness!D33=1,"Sì","No") -> Sì | D50: 1 | E50: Completeness!B33 | F50: Imputare con un valore come "Unknown" | I50: una tecnica è considerata valida se risolve il problema | P50: =IF(MOD(ROW(), 2)=0, "Pari", "Dispari") -> Pari
A51: brokered_by | B51: fa imputation dei NaN con una tecnica ottimale | C51: =IF(Completeness!D33=1,"Sì","No") -> Sì | D51: 1 | E51: Completeness!B33 | F51: Imputare con un valore come "Unknown" | I51: una tecnica è considerata ottimale se risolve il problema minimizzando il più possibile l'aggiunta di bias | P51: =IF(MOD(ROW(), 2)=0, "Pari", "Dispari") -> Dispari
A52: brokered_by | B52: fa imputation dei -1 con una tecnica valida | C52: =IF(Completeness!D34=1,"Sì","No") -> No | D52: 0 | E52: Completeness!B34 | F52: Imputare con un valore come "Unknown" | I52: una tecnica ottimale è anche valida (mettere ad entrambi i descrittori 1) | P52: =IF(MOD(ROW(), 2)=0, "Pari", "Dispari") -> Pari
A53: brokered_by | B53: fa imputation dei -1 con una tecnica ottimale | C53: =IF(Completeness!D34=1,"Sì","No") -> No | D53: 0 | E53: Completeness!B34 | F53: Imputare con un valore come "Unknown" | P53: =IF(MOD(ROW(), 2)=0, "Pari", "Dispari") -> Dispari
...

Sheet Prescriptivity
A1: OUTLIER DETECTION
A3: colonna | B3: descrittore | C3: valutare? | D3: check | E3: dipendenza
A4: price | B4: la strategia è prescrittiva / gli outlier sono elencati con convinzione | C4: =IF(Completeness!D4=1,"Sì","No") -> Sì | D4: 1 | E4: applica una strategia di outlier detection / dà direttamente gli outlier (B4)
A5: bed | B5: la strategia è prescrittiva / gli outlier sono elencati con convinzione | C5: =IF(Completeness!D5=1,"Sì","No") -> Sì | D5: 1 | E5: applica una strategia di outlier detection / dà direttamente gli outlier (B5)
A6: bath | B6: la strategia è prescrittiva / gli outlier sono elencati con convinzione | C6: =IF(Completeness!D6=1,"Sì","No") -> Sì | D6: 1 | E6: applica una strategia di outlier detection / dà direttamente gli outlier (B6)
A7: acre_lot | B7: la strategia è prescrittiva / gli outlier sono elencati con convinzione | C7: =IF(Completeness!D7=1,"Sì","No") -> Sì | D7: 1 | E7: applica una strategia di outlier detection / dà direttamente gli outlier (B7)
A8: house_size | B8: la strategia è prescrittiva / gli outlier sono elencati con convinzione | C8: =IF(Completeness!D8=1,"Sì","No") -> Sì | D8: 1 | E8: applica una strategia di outlier detection / dà direttamente gli outlier (B8)
A11: Prescriptivity parziale Outlier Detection: | B11: =IFERROR(SUM(D4:D8)/COUNTIF(C4:C8,"Sì"), 0) -> 1 | C11: =IF(COUNTIF(C4:C8, "Sì")>0, "Sì", "No") -> Sì
A14: DATA STANDARDIZATION
A16: colonna | B16: descrittore | C16: valutare? | D16: check | E16: dipendenza
A17: status | B17: propone una soluzione prescrittiva per la mancanza di uno standard | C17: =IF(Completeness!D17=1,"Sì","No") -> Sì | D17: 1 | E17: propone una soluzione per i valori troncati alla prima lettera ('s' e 'f', dovrebbero essere 'sold' e 'for_sale') (B17)
A18: price | B18: propone una soluzione prescrittiva per la mancanza di uno standard | C18: =IF(Completeness!D18=1,"Sì","No") -> Sì | D18: 1 | E18: propone una soluzione per la presenza del simbolo '$' (B18)
A19: bed | B19: propone una soluzione prescrittiva per la mancanza di uno standard | C19: =IF(Completeness!D19=1,"Sì","No") -> Sì | D19: 1 | E19: propone una soluzione per la presenza di numeri rappresentati come parole in una colonna numerica (B19)
A20: bath | B20: propone una soluzione prescrittiva per la mancanza di uno standard | C20: =IF(Completeness!D20=1,"Sì","No") -> Sì | D20: 1 | E20: propone una soluzione per la presenza di numeri rappresentati come parole in una colonna numerica (B20)
A21: street | B21: propone una soluzione prescrittiva per la mancanza di uno standard | C21: =IF(Completeness!D21=1,"Sì","No") -> No | D21: 0 | E21: propone una soluzione per la presenza del numero civico alla fine o inizio dell'indirizzo (B21)
A22: state | B22: propone una soluzione prescrittiva per la mancanza di uno standard | C22: =IF(Completeness!D22=1,"Sì","No") -> Sì | D22: 1 | E22: propone una soluzione per la presenza di nomi di stati accorciati o allungati (B22)
A23: house_size | B23: propone una soluzione prescrittiva per la mancanza di uno standard | C23: =IF(Completeness!D23=1,"Sì","No") -> Sì | D23: 1 | E23: propone una soluzione per la mancanza di una unità di misura univoca (B23)
A24: prev_sold_date | B24: propone una soluzione prescrittiva per la mancanza di uno standard | C24: =IF(Completeness!D24=1,"Sì","No") -> Sì | D24: 1 | E24: propone una soluzione per la mancanza di un formato unico per le date (B24)
A27: Prescriptivity parziale Data Standardization: | B27: =IFERROR(SUM(D17:D24)/COUNTIF(C17:C24,"Sì"), 0) -> 1 | C27: =IF(COUNTIF(C17:C24, "Sì")>0, "Sì", "No") -> Sì
A30: DATA IMPUTATION
A32: colonna | B32: descrittore | C32: valutare? | D32: check
A33: brokered_by | B33: l'imputation dei NaN è prescrittiva | C33: =IF(Completeness!D33=1,"Sì","No") -> Sì | D33: 1 | E33: Completeness!B33
A34: brokered_by | B34: l'imputation dei -1 è prescrittiva | C34: =IF(Completeness!D34=1,"Sì","No") -> No | D34: 0 | E34: Completeness!B34
A35: brokered_by | B35: l'imputation delle stringhe vuote è prescrittiva | C35: =IF(Completeness!D35=1,"Sì","No") -> Sì | D35: 1 | E35: Completeness!B35
A36: status | B36: l'imputation degli 'Unknown' è prescrittiva | C36: =IF(Completeness!D36=1,"Sì","No") -> Sì | D36: 1 | E36: Completeness!B36
A37: status | B37: l'imputation dei '-' è prescrittiva | C37: =IF(Completeness!D37=1,"Sì","No") -> Sì | D37: 1 | E37: Completeness!B37
A38: status | B38: l'imputation delle stringhe vuote è prescrittiva | C38: =IF(Completeness!D38=1,"Sì","No") -> Sì | D38: 1 | E38: Completeness!B38
A39: price | B39: l'imputation dei NaN è prescrittiva | C39: =IF(Completeness!D39=1,"Sì","No") -> Sì | D39: 1 | E39: Completeness!B39
A40: price | B40: l'imputation dei -1 è prescrittiva | C40: =IF(Completeness!D40=1,"Sì","No") -> Sì | D40: 1 | E40: Completeness!B40
A41: price | B41: l'imputation delle stringhe vuote è prescrittiva | C41: =IF(Completeness!D41=1,"Sì","No") -> Sì | D41: 1 | E41: Completeness!B41
A42: bed | B42: l'imputation dei NaN è prescrittiva | C42: =IF(Completeness!D42=1,"Sì","No") -> Sì | D42: 1 | E42: Completeness!B42
A43: bed | B43: l'imputation dei -1 è prescrittiva | C43: =IF(Completeness!D43=1,"Sì","No") -> Sì | D43: 1 | E43: Completeness!B43
A44: bed | B44: l'imputation delle stringhe vuote è prescrittiva | C44: =IF(Completeness!D44=1,"Sì","No") -> Sì | D44: 1 | E44: Completeness!B44
... A68: prev_sold_date | B68: l'imputation delle stringhe vuote è prescrittiva | C68: =IF(Completeness!D68=1,"Sì","No") -> No | D68: 0 | E68: Completeness!B68
A71: Prescriptivity parziale Data Imputation: | B71: =IFERROR(SUM(D33:D68)/COUNTIF(C33:C68,"Sì"), 0) -> 1 | C71: =IF(COUNTIF(C33:C68, "Sì")>0, "Sì", "No") -> Sì
A74: DATA DEDUPLICATION
B76: descrittore | C76: valutare? | D76: check | E76: dipendenza
B77: processo di exact matching prescrittivo | C77: =IF(Completeness!D77=1,"Sì","No") -> No | D77: 0 | E77: Completeness!B77
B78: processo di non-exact matching prescrittivo | C78: =IF(Completeness!D78=1,"Sì","No") -> Sì | D78: 1 | E78: Completeness!B78
A81: Prescriptivity parziale Data Deduplication: | B81: =IFERROR(SUM(D77:D78)/COUNTIF(C77:C78,"Sì"), 0) -> 1 | C81: =IF(COUNTIF(C77:C78, "Sì")>0, "Sì", "No") -> Sì
...

Sheet Readiness
A1: OUTLIER DETECTION
A3: colonna | B3: descrittore | C3: valutare? | D3: check | E3: dipendenza
A4: price | B4: la soluzione proposta è codice o i singoli valori della colonna puliti (o l'intero dataset) | C4: =IF(Completeness!D4=1,"Sì","No") -> Sì | D4: 1 | E4: Completeness!B4 | G4: =IF(MOD(ROW(), 2)=0, "Pari", "Dispari") -> Pari
A5: price | B5: la soluzione proposta fornisce i valori della colonna puliti (o l'intero dataset) | C5: =IF(Completeness!D4=1,"Sì","No") -> Sì | D5: 0 | E5: Completeness!B4 | G5: =IF(MOD(ROW(), 2)=0, "Pari", "Dispari") -> Dispari
A6: bed | B6: la soluzione proposta è codice o i singoli valori della colonna puliti (o l'intero dataset) | C6: =IF(Completeness!D5=1,"Sì","No") -> Sì | D6: 1 | E6: Completeness!B5 | G6: =IF(MOD(ROW(), 2)=0, "Pari", "Dispari") -> Pari
A7: bed | B7: la soluzione proposta fornisce i valori della colonna puliti (o l'intero dataset) | C7: =IF(Completeness!D5=1,"Sì","No") -> Sì | D7: 0 | E7: Completeness!B5 | G7: =IF(MOD(ROW(), 2)=0, "Pari", "Dispari") -> Dispari
A8: bath | B8: la soluzione proposta è codice o i singoli valori della colonna puliti (o l'intero dataset) | C8: =IF(Completeness!D6=1,"Sì","No") -> Sì | D8: 1 | E8: Completeness!B6 | G8: =IF(MOD(ROW(), 2)=0, "Pari", "Dispari") -> Pari
A9: bath | B9: la soluzione proposta fornisce i valori della colonna puliti (o l'intero dataset) | C9: =IF(Completeness!D6=1,"Sì","No") -> Sì | D9: 0 | E9: Completeness!B6 | G9: =IF(MOD(ROW(), 2)=0, "Pari", "Dispari") -> Dispari
A10: acre_lot | B10: la soluzione proposta è codice o i singoli valori della colonna puliti (o l'intero dataset) | C10: =IF(Completeness!D7=1,"Sì","No") -> Sì | D10: 1 | E10: Completeness!B7 | G10: =IF(MOD(ROW(), 2)=0, "Pari", "Dispari") -> Pari
A11: acre_lot | B11: la soluzione proposta fornisce i valori della colonna puliti (o l'intero dataset) | C11: =IF(Completeness!D7=1,"Sì","No") -> Sì | D11: 0 | E11: Completeness!B7 | G11: =IF(MOD(ROW(), 2)=0, "Pari", "Dispari") -> Dispari
A12: house_size | B12: la soluzione proposta è codice o i singoli valori della colonna puliti (o l'intero dataset) | C12: =IF(Completeness!D8=1,"Sì","No") -> Sì | D12: 1 | E12: Completeness!B8 | G12: =IF(MOD(ROW(), 2)=0, "Pari", "Dispari") -> Pari
A13: house_size | B13: la soluzione proposta fornisce i valori della colonna puliti (o l'intero dataset) | C13: =IF(Completeness!D8=1,"Sì","No") -> Sì | D13: 0 | E13: Completeness!B8 | G13: =IF(MOD(ROW(), 2)=0, "Pari", "Dispari") -> Dispari
A16: Readiness parziale Outlier Detection: | B16: =IFERROR((SUMIF(G4:G13, "Pari", D4:D13)*0.8 + SUMIF(G4:G13, "Dispari", D4:D13)*0.2) / (COUNTIF(C4:C13,"Sì")/2), 0) -> 0.8 | C16: =IF(COUNTIF(C4:C13, "Sì")>0, "Sì", "No") -> Sì
A19: DATA STANDARDIZATION:
A21: colonna | B21: descrittore | C21: valutare? | D21: check | E21: dipendenza
A22: status | B22: la soluzione proposta è codice o i singoli valori della colonna puliti (o l'intero dataset) | C22: =IF(Completeness!D17=1,"Sì","No") -> Sì | D22: 1 | E22: propone una soluzione per i valori troncati alla prima lettera ('s' e 'f', dovrebbero essere 'sold' e 'for_sale') (B17) | N22: =IF(MOD(ROW(), 2)=0, "Pari", "Dispari") -> Pari
A23: status | B23: la soluzione proposta fornisce i valori della colonna puliti (o l'intero dataset) | C23: =IF(Completeness!D17=1,"Sì","No") -> Sì | D23: 0 | E23: propone una soluzione per i valori troncati alla prima lettera ('s' e 'f', dovrebbero essere 'sold' e 'for_sale') (B17) | N23: =IF(MOD(ROW(), 2)=0, "Pari", "Dispari") -> Dispari
A24: price | B24: la soluzione proposta è codice o i singoli valori della colonna puliti (o l'intero dataset) | C24: =IF(Completeness!D18=1,"Sì","No") -> Sì | D24: 1 | E24: propone una soluzione per la presenza del simbolo '$' (B18) | N24: =IF(MOD(ROW(), 2)=0, "Pari", "Dispari") -> Pari
A25: price | B25: la soluzione proposta fornisce i valori della colonna puliti (o l'intero dataset) | C25: =IF(Completeness!D18=1,"Sì","No") -> Sì | D25: 0 | E25: propone una soluzione per la presenza del simbolo '$' (B18) | N25: =IF(MOD(ROW(), 2)=0, "Pari", "Dispari") -> Dispari
A26: bed | B26: la soluzione proposta è codice o i singoli valori della colonna puliti (o l'intero dataset) | C26: =IF(Completeness!D19=1,"Sì","No") -> Sì | D26: 1 | E26: propone una soluzione per la presenza di numeri rappresentati come parole in una colonna numerica (B19) | N26: =IF(MOD(ROW(), 2)=0, "Pari", "Dispari") -> Pari
A27: bed | B27: la soluzione proposta fornisce i valori della colonna puliti (o l'intero dataset) | C27: =IF(Completeness!D19=1,"Sì","No") -> Sì | D27: 0 | E27: propone una soluzione per la presenza di numeri rappresentati come parole in una colonna numerica (B19) | N27: =IF(MOD(ROW(), 2)=0, "Pari", "Dispari") -> Dispari
A28: bath | B28: la soluzione proposta è codice o i singoli valori della colonna puliti (o l'intero dataset) | C28: =IF(Completeness!D20=1,"Sì","No") -> Sì | D28: 1 | E28: propone una soluzione per la presenza di numeri rappresentati come parole in una colonna numerica (B20) | N28: =IF(MOD(ROW(), 2)=0, "Pari", "Dispari") -> Pari
A29: bath | B29: la soluzione proposta fornisce i valori della colonna puliti (o l'intero dataset) | C29: =IF(Completeness!D20=1,"Sì","No") -> Sì | D29: 0 | E29: propone una soluzione per la presenza di numeri rappresentati come parole in una colonna numerica (B20) | N29: =IF(MOD(ROW(), 2)=0, "Pari", "Dispari") -> Dispari
A30: street | B30: la soluzione proposta è codice o i singoli valori della colonna puliti (o l'intero dataset) | C30: =IF(Completeness!D21=1,"Sì","No") -> No | D30: 0 | E30: propone una soluzione per la presenza del numero civico alla fine o inizio dell'indirizzo (B21) | N30: =IF(MOD(ROW(), 2)=0, "Pari", "Dispari") -> Pari
A31: street | B31: la soluzione proposta fornisce i valori della colonna puliti (o l'intero dataset) | C31: =IF(Completeness!D21=1,"Sì","No") -> No | D31: 0 | E31: propone una soluzione per la presenza del numero civico alla fine o inizio dell'indirizzo (B21) | N31: =IF(MOD(ROW(), 2)=0, "Pari", "Dispari") -> Dispari
A32: state | B32: la soluzione proposta è codice o i singoli valori della colonna puliti (o l'intero dataset) | C32: =IF(Completeness!D22=1,"Sì","No") -> Sì | D32: 1 | E32: propone una soluzione per la presenza di nomi di stati accorciati o allungati (B22) | N32: =IF(MOD(ROW(), 2)=0, "Pari", "Dispari") -> Pari
A33: state | B33: la soluzione proposta fornisce i valori della colonna puliti (o l'intero dataset) | C33: =IF(Completeness!D22=1,"Sì","No") -> Sì | D33: 0 | E33: propone una soluzione per la presenza di nomi di stati accorciati o allungati (B22) | N33: =IF(MOD(ROW(), 2)=0, "Pari", "Dispari") -> Dispari
A34: house_size | B34: la soluzione proposta è codice o i singoli valori della colonna puliti (o l'intero dataset) | C34: =IF(Completeness!D23=1,"Sì","No") -> Sì | D34: 1 | E34: propone una soluzione per la mancanza di una unità di misura univoca (B23) | N34: =IF(MOD(ROW(), 2)=0, "Pari", "Dispari") -> Pari
A35: house_size | B35: la soluzione proposta fornisce i valori della colonna puliti (o l'intero dataset) | C35: =IF(Completeness!D23=1,"Sì","No") -> Sì | D35: 0 | E35: propone una soluzione per la mancanza di una unità di misura univoca (B23) | N35: =IF(MOD(ROW(), 2)=0, "Pari", "Dispari") -> Dispari
A36: prev_sold_date | B36: la soluzione proposta è codice o i singoli valori della colonna puliti (o l'intero dataset) | C36: =IF(Completeness!D24=1,"Sì","No") -> Sì | D36: 1 | E36: propone una soluzione per la mancanza di un formato unico per le date (B24) | N36: =IF(MOD(ROW(), 2)=0, "Pari", "Dispari") -> Pari
A37: prev_sold_date | B37: la soluzione proposta fornisce i valori della colonna puliti (o l'intero dataset) | C37: =IF(Completeness!D24=1,"Sì","No") -> Sì | D37: 0 | E37: propone una soluzione per la mancanza di un formato unico per le date (B24) | N37: =IF(MOD(ROW(), 2)=0, "Pari", "Dispari") -> Dispari
A40: Readiness parziale Data Standardization: | B40: =IFERROR((SUMIF(N22:N37, "Pari", D22:D37)*0.8 + SUMIF(N22:N37, "Dispari", D22:D37)*0.2) / (COUNTIF(C22:C37,"Sì")/2), 0) -> 0.8 | C40: =IF(COUNTIF(C22:C37, "Sì")>0, "Sì", "No") -> Sì
A43: DATA IMPUTATION
A45: colonna | B45: descrittore | C45: valutare? | D45: check
A46: brokered_by | B46: fornisce codice per l'imputation dei NaN oppure restituisce la colonna/dataset pulito | C46: =IF(Completeness!D33=1,"Sì","No") -> Sì | D46: 1 | E46: Completeness!B33 | G46: =IF(MOD(ROW(), 2)=0, "Pari", "Dispari") -> Pari | H46: una tecnica è considerata valida se risolve il problema
A47: brokered_by | B47: restituisce la colonna/dataset pulito | C47: =IF(Completeness!D33=1,"Sì","No") -> Sì | D47: 0 | E47: Completeness!B33 | G47: =IF(MOD(ROW(), 2)=0, "Pari", "Dispari") -> Dispari | H47: una tecnica è considerata ottimale se risolve il problema minimizzando il più possibile l'aggiunta di bias
A48: brokered_by | B48: fornisce codice per l'imputation dei -1 oppure restituisce la colonna/dataset pulito | C48: =IF(Completeness!D34=1,"Sì","No") -> No | D48: 0 | E48: Completeness!B34 | G48: =IF(MOD(ROW(), 2)=0, "Pari", "Dispari") -> Pari | H48: una tecnica ottimale è anche valida (mettere ad entrambi i descrittori 1)
A49: brokered_by | B49: restituisce la colonna/dataset pulito | C49: =IF(Completeness!D34=1,"Sì","No") -> No | D49: 0 | E49: Completeness!B34 | G49: =IF(MOD(ROW(), 2)=0, "Pari", "Dispari") -> Dispari
A50: brokered_by | B50: fornisce codice per l'imputation delle stringhe vuote oppure restituisce la colonna/dataset pulito | C50: =IF(Completeness!D35=1,"Sì","No") -> Sì | D50: 1 | E50: Completeness!B35 | G50: =IF(MOD(ROW(), 2)=0, "Pari", "Dispari") -> Pari
A51: brokered_by | B51: restituisce la colonna/dataset pulito | C51: =IF(Completeness!D35=1,"Sì","No") -> Sì | D51: 0 | E51: Completeness!B35 | G51: =IF(MOD(ROW(), 2)=0, "Pari", "Dispari") -> Dispari
...

Sheet Specificity
A1: OUTLIER DETECTION | B1: N.B. Bisogna includere la colonna che si sta valutando
A3: colonna | B3: descrittore | C3: valutare? | D3: num col | E3: punteggio | F3: dipendenza
A4: price | B4: numero di colonne per cui la strategia di outlier detection è specifica per la colonna | C4: =IF(Completeness!D4=1,"Sì","No") -> Sì | D4: 5 | E4: =1-((D4-1)/4) -> 0 | F4: applica una strategia di outlier detection / dà direttamente gli outlier (B4)
A5: bed | B5: numero di colonne per cui la strategia di outlier detection è specifica per la colonna | C5: =IF(Completeness!D5=1,"Sì","No") -> Sì | D5: 5 | E5: =1-((D5-1)/4) -> 0 | F5: applica una strategia di outlier detection / dà direttamente gli outlier (B5)
A6: bath | B6: numero di colonne per cui la strategia di outlier detection è specifica per la colonna | C6: =IF(Completeness!D6=1,"Sì","No") -> Sì | D6: 5 | E6: =1-((D6-1)/4) -> 0 | F6: applica una strategia di outlier detection / dà direttamente gli outlier (B6)
A7: acre_lot | B7: numero di colonne per cui la strategia di outlier detection è specifica per la colonna | C7: =IF(Completeness!D7=1,"Sì","No") -> Sì | D7: 5 | E7: =1-((D7-1)/4) -> 0 | F7: applica una strategia di outlier detection / dà direttamente gli outlier (B7)
A8: house_size | B8: numero di colonne per cui la strategia di outlier detection è specifica per la colonna | C8: =IF(Completeness!D8=1,"Sì","No") -> Sì | D8: 5 | E8: =1-((D8-1)/4) -> 0 | F8: applica una strategia di outlier detection / dà direttamente gli outlier (B8)
A11: Specificity parziale Outlier Detection: | B11: =IFERROR(SUM(E4:E8)/COUNTIF(C4:C8,"Sì"), 0) -> 0 | C11: =IF(COUNTIF(C4:C8, "Sì")>0, "Sì", "No") -> Sì
A14: DATA IMPUTATION | B14: N.B. Bisogna includere la colonna che si sta valutando
A16: colonna | B16: descrittore | C16: valutare? | D16: num col | E16: punteggio
A17: brokered_by | B17: numero di colonne per cui la soluzione per i NaN è condivisa | C17: =IF(Completeness!D33=1,"Sì","No") -> Sì | D17: 2 | E17: =1-((D17-1)/11) -> 0.90909091 | F17: Completeness!B33
A18: brokered_by | B18: numero di colonne per cui la soluzione per i -1 è condivisa | C18: =IF(Completeness!D34=1,"Sì","No") -> No | D18: 12 | E18: =1-((D18-1)/11) -> 0 | F18: Completeness!B34
A19: brokered_by | B19: numero di colonne per cui la soluzione per le stringhe vuote è condivisa | C19: =IF(Completeness!D35=1,"Sì","No") -> Sì | D19: 6 | E19: =1-((D19-1)/11) -> 0.54545455 | F19: Completeness!B35
A20: status | B20: numero di colonne per cui la soluzione per gli 'Unknown' è condivisa | C20: =IF(Completeness!D36=1,"Sì","No") -> Sì | D20: 4 | E20: =1-((D20-1)/11) -> 0.72727273 | F20: Completeness!B36
A21: status | B21: numero di colonne per cui la soluzione per i '-' è condivisa | C21: =IF(Completeness!D37=1,"Sì","No") -> Sì | D21: 4 | E21: =1-((D21-1)/11) -> 0.72727273 | F21: Completeness!B37
A22: status | B22: numero di colonne per cui la soluzione per le stringhe vuote è condivisa | C22: =IF(Completeness!D38=1,"Sì","No") -> Sì | D22: 6 | E22: =1-((D22-1)/11) -> 0.54545455 | F22: Completeness!B38
A23: price | B23: numero di colonne per cui la soluzione per i NaN è condivisa | C23: =IF(Completeness!D39=1,"Sì","No") -> Sì | D23: 5 | E23: =1-((D23-1)/11) -> 0.63636364 | F23: Completeness!B39
A24: price | B24: numero di colonne per cui la soluzione per i -1 è condivisa | C24: =IF(Completeness!D40=1,"Sì","No") -> Sì | D24: 5 | E24: =1-((D24-1)/11) -> 0.63636364 | F24: Completeness!B40
A25: price | B25: numero di colonne per cui la soluzione per le stringhe vuote è condivisa | C25: =IF(Completeness!D41=1,"Sì","No") -> Sì | D25: 5 | E25: =1-((D25-1)/11) -> 0.63636364 | F25: Completeness!B41
A26: bed | B26: numero di colonne per cui la soluzione per i NaN è condivisa | C26: =IF(Completeness!D42=1,"Sì","No") -> Sì | D26: 5 | E26: =1-((D26-1)/11) -> 0.63636364 | F26: Completeness!B42
A27: bed | B27: numero di colonne per cui la soluzione per i -1 è condivisa | C27: =IF(Completeness!D43=1,"Sì","No") -> Sì | D27: 5 | E27: =1-((D27-1)/11) -> 0.63636364 | F27: Completeness!B43
A28: bed | B28: numero di colonne per cui la soluzione per le stringhe vuote è condivisa | C28: =IF(Completeness!D44=1,"Sì","No") -> Sì | D28: 5 | E28: =1-((D28-1)/11) -> 0.63636364 | F28: Completeness!B44
... A52: prev_sold_date | B52: numero di colonne per cui la soluzione per le stringhe vuote è condivisa | C52: =IF(Completeness!D68=1,"Sì","No") -> No | D52: 12 | E52: =1-((D52-1)/11) -> 0 | F52: Completeness!B68
A55: Specificity parziale Data Imputation: | B55: =IFERROR(SUM(E17:E52)/COUNTIF(C17:C52,"Sì"), 0) -> 0.65982405 | C55: =IF(COUNTIF(C17:C52, "Sì")>0, "Sì", "No") -> Sì
A58: Specificity totale: | B58: =IFERROR((B11+B55)/(COUNTIF(C11, "Sì")+COUNTIF(C55, "Sì")), "Non calcolabile") -> 0.32991202

Sheet Flag
A1: Hallucination flag
A2: l'LLM allucina | B2: No
A5: Clarity flag
A6: l'LLM è poco chiaro nella gestione dei missing values | B6: No
