Workbook

Sheet Completeness
A1: colonna | B1: descrittore | C1: check
B2: menziona l'argomento (domain classification) del dataset | C2: 1
B3: menziona il numero di colonne del dataset | C3: 1
B4: menziona il numero di righe del dataset | C4: 1
B5: menziona il numero totale di missing values | C5: 0
B6: menziona il numero di duplicati (esatti) | C6: 0
B7: menziona le unique column combinations | C7: 1
B8: menziona la correlation analysis | C8: 1
A9: brokered_by | B9: menziona i missing values | C9: 1
A10: brokered_by | B10: menziona i distinct values | C10: 1
A11: brokered_by | B11: menziona il data type della colonna | C11: 1
A12: brokered_by | B12: fa la domain classification/descrive la colonna | C12: 0
A13: brokered_by | B13: menziona la frequency dei valori | C13: 0
A14: status | B14: menziona i missing values | C14: 1
A15: status | B15: menziona i distinct values | C15: 1
A16: status | B16: menziona il data type della colonna | C16: 1
A17: status | B17: fa la domain classification/descrive la colonna | C17: 0
A18: status | B18: menziona la frequency dei valori | C18: 1
A19: price | B19: menziona i missing values | C19: 1
A20: price | B20: menziona i distinct values | C20: 1
... A98: prev_sold_date | B98: menziona la frequency dei valori | C98: 1
A101: Completeness: | B101: =SUM(C2:C98)/COUNT(C2:C98) -> 0.84536082

Sheet Accuracy
A1: colonna | B1: descrittore | C1: valutare? | D1: check | E1: dipende da
B2: descrive correttamente il dataset | C2: =IF(Completeness!C2=1, "Sì", "No") -> Sì | D2: 1 | E2: menziona l'argomento (domain classification) del dataset (B2)
B3: il numero di colonne è giusto (12) / il metodo è giusto | C3: =IF(Completeness!C3=1, "Sì", "No") -> Sì | D3: 1 | E3: menziona il numero di colonne del dataset (B3)
B4: il numero di righe è giusto (100) / il metodo è giusto | C4: =IF(Completeness!C4=1, "Sì", "No") -> Sì | D4: 1 | E4: menziona il numero di righe del dataset (B4)
B5: il numero o la percentuale di missing values è giusto (195 - 16,25%) / il metodo è giusto | C5: =IF(Completeness!C5=1, "Sì", "No") -> No | D5: 0 | E5: menziona il numero totale di missing values (B5)
B6: il numero di duplicati (esatti) è giusto (0 righe duplicate) / il metodo è giusto | C6: =IF(Completeness!C6=1, "Sì", "No") -> No | D6: 0 | E6: menziona il numero di duplicati (esatti) (B6)
B7: segnala 'status', 'acre_lot', 'zip_code' come ucc / il metodo per trovarle è giusto | C7: =IF(Completeness!C7=1, "Sì", "No") -> Sì | D7: 0 | E7: menziona le unique column combinations (B7) | F7: N.B. ci sono anche altre ucc, qui è segnata quella minima
B8: segnala correlazione fra: state - zip-code, bath - house_size, house_size - state / il metodo è giusto | C8: =IF(Completeness!C8=1, "Sì", "No") -> Sì | D8: 0 | E8: menziona la correlation analysis (B8)
A9: brokered_by | B9: il numero o la percentuale di missing values è giusto (30 - 30%) / il metodo è giusto | C9: =IF(Completeness!C9=1, "Sì", "No") -> Sì | D9: 0 | E9: menziona i missing values (B9)
A10: brokered_by | B10: il numero o la percentuale di distinct values è giusto (61 - 61%) / il metodo è giusto | C10: =IF(Completeness!C10=1, "Sì", "No") -> Sì | D10: 1 | E10: menziona i distinct values (B10)
A11: brokered_by | B11: menziona che il data type è categorico | C11: =IF(Completeness!C11=1, "Sì", "No") -> Sì | D11: 0 | E11: menziona il data type della colonna (B11)
A12: brokered_by | B12: descrive correttamente la colonna: ID di agenti immobiliari | C12: =IF(Completeness!C12=1, "Sì", "No") -> No | D12: 0 | E12: fa la domain classification/descrive la colonna (B12)
A13: brokered_by | B13: l'istogramma delle frequencies è corretto / il metodo è giusto | C13: =IF(Completeness!C13=1, "Sì", "No") -> No | D13: 0 | E13: menziona la frequency dei valori (B13)
A14: status | B14: il numero o la percentuale di missing values è giusto (15 - 15%) / il metodo è giusto | C14: =IF(Completeness!C14=1, "Sì", "No") -> Sì | D14: 0 | E14: menziona i missing values (B14)
A15: status | B15: il numero o la percentuale o l'elenco di distinct values è giusto (6 - 6%) / il metodo è giusto | C15: =IF(Completeness!C15=1, "Sì", "No") -> Sì | D15: 0 | E15: menziona i distinct values (B15)
A16: status | B16: menziona che il data type è categorico | C16: =IF(Completeness!C16=1, "Sì", "No") -> Sì | D16: 0 | E16: menziona il data type della colonna (B16)
A17: status | B17: descrive correttamente la colonna: status della vendita | C17: =IF(Completeness!C17=1, "Sì", "No") -> No | D17: 0 | E17: fa la domain classification/descrive la colonna (B17)
A18: status | B18: l'istogramma delle frequencies è corretto / il metodo è giusto | C18: =IF(Completeness!C18=1, "Sì", "No") -> Sì | D18: 1 | E18: menziona la frequency dei valori (B18)
A19: price | B19: il numero o la percentuale di missing values è giusto (7 - 7%) / il metodo è giusto | C19: =IF(Completeness!C19=1, "Sì", "No") -> Sì | D19: 0 | E19: menziona i missing values (B19)
A20: price | B20: il numero o la percentuale di distinct values è giusto (68 - 68%) / il metodo è giusto | C20: =IF(Completeness!C20=1, "Sì", "No") -> Sì | D20: 0 | E20: menziona i distinct values (B20)
... A98: prev_sold_date | B98: l'istogramma delle frequencies è corretto / il metodo è giusto | C98: =IF(Completeness!C98=1, "Sì", "No") -> Sì | D98: 1 | E98: menziona la frequency dei valori (B98)
A101: Accuracy: | B101: =SUM(D2:D98)/COUNTIF(C2:C98, "Sì") -> 0.42682927
A103: Nota | B103: Diverse rappresentazioni dei null values vengono tutte convertite in nan, di fatto alterando il conto dei distinct values e gli istogrammi. Inoltre, non viene considerato -1 come valore numerico ma "-1" come stringa. Questo invalida quasi tutte le misure statistiche nelle colonne numeriche in cui sono presenti i valori -1.

Sheet Readiness
A1: colonna | B1: descrittore | C1: valutare? | D1: check | E1: dipende da
B2: esplicita il numero/percentuale di colonne oppure fornisce il codice | C2: =IF(Completeness!C3=1, "Sì", "No") -> Sì | D2: 1 | E2: menziona il numero di colonne del dataset (B3) | J2: =IF(MOD(ROW(), 2)=0, "Pari", "Dispari") -> Pari
B3: esplicita il numero/percentuale di colonne | C3: =IF(Completeness!C3=1, "Sì", "No") -> Sì | D3: 1 | E3: menziona il numero di colonne del dataset (B3) | J3: =IF(MOD(ROW(), 2)=0, "Pari", "Dispari") -> Dispari
B4: esplicita il numero/percentuale di righe oppure fornisce il codice | C4: =IF(Completeness!C4=1, "Sì", "No") -> Sì | D4: 1 | E4: menziona il numero di righe del dataset (B4) | J4: =IF(MOD(ROW(), 2)=0, "Pari", "Dispari") -> Pari
B5: esplicita il numero/percentuale di righe | C5: =IF(Completeness!C4=1, "Sì", "No") -> Sì | D5: 1 | E5: menziona il numero di righe del dataset (B4) | J5: =IF(MOD(ROW(), 2)=0, "Pari", "Dispari") -> Dispari
B6: esplicita il numero/percentuale di missing values oppure fornisce il codice | C6: =IF(Completeness!C5=1, "Sì", "No") -> No | D6: 0 | E6: menziona il numero totale di missing values (B5) | J6: =IF(MOD(ROW(), 2)=0, "Pari", "Dispari") -> Pari
B7: esplicita il numero/percentuale di missing values | C7: =IF(Completeness!C5=1, "Sì", "No") -> No | D7: 0 | E7: menziona il numero totale di missing values (B5) | J7: =IF(MOD(ROW(), 2)=0, "Pari", "Dispari") -> Dispari
B8: esplicita il numero di duplicati esatti oppure fornisce il codice | C8: =IF(Completeness!C6=1, "Sì", "No") -> No | D8: 0 | E8: menziona il numero di duplicati (esatti) (B6) | J8: =IF(MOD(ROW(), 2)=0, "Pari", "Dispari") -> Pari
B9: esplicita il numero di duplicati esatti | C9: =IF(Completeness!C6=1, "Sì", "No") -> No | D9: 0 | E9: menziona il numero di duplicati (esatti) (B6) | J9: =IF(MOD(ROW(), 2)=0, "Pari", "Dispari") -> Dispari
B10: esplicita le ucc trovate oppure fornisce il codice | C10: =IF(Completeness!C7=1, "Sì", "No") -> Sì | D10: 1 | E10: menziona le unique column combinations (B7) | J10: =IF(MOD(ROW(), 2)=0, "Pari", "Dispari") -> Pari
B11: esplicita le ucc trovate | C11: =IF(Completeness!C7=1, "Sì", "No") -> Sì | D11: 1 | E11: menziona le unique column combinations (B7) | J11: =IF(MOD(ROW(), 2)=0, "Pari", "Dispari") -> Dispari
B12: esplicita le correlazioni trovate oppure fornisce il codice | C12: =IF(Completeness!C8=1, "Sì", "No") -> Sì | D12: 1 | E12: menziona la correlation analysis (B8) | J12: =IF(MOD(ROW(), 2)=0, "Pari", "Dispari") -> Pari
B13: esplicita le correlazioni trovate | C13: =IF(Completeness!C8=1, "Sì", "No") -> Sì | D13: 1 | E13: menziona la correlation analysis (B8) | J13: =IF(MOD(ROW(), 2)=0, "Pari", "Dispari") -> Dispari
A14: brokered_by | B14: esplicita il num/percentuale di missing values oppure fornisce codice | C14: =IF(Completeness!C9=1, "Sì", "No") -> Sì | D14: 1 | E14: menziona i missing values (B9) | J14: =IF(MOD(ROW(), 2)=0, "Pari", "Dispari") -> Pari
A15: brokered_by | B15: esplicita il num/percentuale di missing values | C15: =IF(Completeness!C9=1, "Sì", "No") -> Sì | D15: 0 | E15: menziona i missing values (B9) | J15: =IF(MOD(ROW(), 2)=0, "Pari", "Dispari") -> Dispari
A16: brokered_by | B16: esplicita il num/percentuale di distinct values oppure fornisce il codice | C16: =IF(Completeness!C10=1, "Sì", "No") -> Sì | D16: 1 | E16: menziona i distinct values (B10) | J16: =IF(MOD(ROW(), 2)=0, "Pari", "Dispari") -> Pari
A17: brokered_by | B17: esplicita il num/percentuale di distinct values | C17: =IF(Completeness!C10=1, "Sì", "No") -> Sì | D17: 1 | E17: menziona i distinct values (B10) | J17: =IF(MOD(ROW(), 2)=0, "Pari", "Dispari") -> Dispari
A18: brokered_by | B18: esplicita il data type della colonna oppure fornisce il codice | C18: =IF(Completeness!C11=1, "Sì", "No") -> Sì | D18: 0 | E18: menziona il data type della colonna (B11) | J18: =IF(MOD(ROW(), 2)=0, "Pari", "Dispari") -> Pari
A19: brokered_by | B19: esplicita il data type della colonna | C19: =IF(Completeness!C11=1, "Sì", "No") -> Sì | D19: 1 | E19: menziona il data type della colonna (B11) | J19: =IF(MOD(ROW(), 2)=0, "Pari", "Dispari") -> Dispari
A20: brokered_by | B20: esplicita la frequency dei valori oppure fornisce il codice | C20: =IF(Completeness!C13=1, "Sì", "No") -> No | D20: 0 | E20: menziona la frequency dei valori (B13) | J20: =IF(MOD(ROW(), 2)=0, "Pari", "Dispari") -> Pari
A21: brokered_by | B21: esplicita la frequency dei valori | C21: =IF(Completeness!C13=1, "Sì", "No") -> No | D21: 0 | E21: menziona la frequency dei valori (B13) | J21: =IF(MOD(ROW(), 2)=0, "Pari", "Dispari") -> Dispari
A22: status | B22: esplicita il num/percentuale di missing values oppure fornisce codice | C22: =IF(Completeness!C14=1, "Sì", "No") -> Sì | D22: 1 | E22: menziona i missing values (B14) | J22: =IF(MOD(ROW(), 2)=0, "Pari", "Dispari") -> Pari
A23: status | B23: esplicita il num/percentuale di missing values | C23: =IF(Completeness!C14=1, "Sì", "No") -> Sì | D23: 0 | E23: menziona i missing values (B14) | J23: =IF(MOD(ROW(), 2)=0, "Pari", "Dispari") -> Dispari
A24: status | B24: esplicita il num/percentuale di distinct values oppure fornisce il codice | C24: =IF(Completeness!C15=1, "Sì", "No") -> Sì | D24: 1 | E24: menziona i distinct values (B15) | J24: =IF(MOD(ROW(), 2)=0, "Pari", "Dispari") -> Pari
A25: status | B25: esplicita il num/percentuale di distinct values | C25: =IF(Completeness!C15=1, "Sì", "No") -> Sì | D25: 0 | E25: menziona i distinct values (B15) | J25: =IF(MOD(ROW(), 2)=0, "Pari", "Dispari") -> Dispari
A26: status | B26: esplicita il data type della colonna oppure fornisce il codice | C26: =IF(Completeness!C16=1, "Sì", "No") -> Sì | D26: 1 | E26: menziona il data type della colonna (B16) | J26: =IF(MOD(ROW(), 2)=0, "Pari", "Dispari") -> Pari
A27: status | B27: esplicita il data type della colonna | C27: =IF(Completeness!C16=1, "Sì", "No") -> Sì | D27: 0 | E27: menziona il data type della colonna (B16) | J27: =IF(MOD(ROW(), 2)=0, "Pari", "Dispari") -> Dispari
A28: status | B28: esplicita la frequency dei valori oppure fornisce il codice | C28: =IF(Completeness!C18=1, "Sì", "No") -> Sì | D28: 1 | E28: menziona la frequency dei valori (B18) | J28: =IF(MOD(ROW(), 2)=0, "Pari", "Dispari") -> Pari
A29: status | B29: esplicita la frequency dei valori | C29: =IF(Completeness!C18=1, "Sì", "No") -> Sì | D29: 0 | E29: menziona la frequency dei valori (B18) | J29: =IF(MOD(ROW(), 2)=0, "Pari", "Dispari") -> Dispari
A30: price | B30: esplicita il num/percentuale di missing values oppure fornisce codice | C30: =IF(Completeness!C19=1, "Sì", "No") -> Sì | D30: 1 | E30: menziona i missing values (B19) | J30: =IF(MOD(ROW(), 2)=0, "Pari", "Dispari") -> Pari
A31: price | B31: esplicita il num/percentuale di missing values | C31: =IF(Completeness!C19=1, "Sì", "No") -> Sì | D31: 0 | E31: menziona i missing values (B19) | J31: =IF(MOD(ROW(), 2)=0, "Pari", "Dispari") -> Dispari
A32: price | B32: esplicita il num/percentuale di distinct values oppure fornisce il codice | C32: =IF(Completeness!C20=1, "Sì", "No") -> Sì | D32: 1 | E32: menziona i distinct values (B20) | J32: =IF(MOD(ROW(), 2)=0, "Pari", "Dispari") -> Pari
A33: price | B33: esplicita il num/percentuale di distinct values | C33: =IF(Completeness!C20=1, "Sì", "No") -> Sì | D33: 0 | E33: menziona i distinct values (B20) | J33: =IF(MOD(ROW(), 2)=0, "Pari", "Dispari") -> Dispari
A34: price | B34: esplicita il data type della colonna oppure fornisce il codice | C34: =IF(Completeness!C21=1, "Sì", "No") -> Sì | D34: 1 | E34: menziona il data type della colonna (B21) | J34: =IF(MOD(ROW(), 2)=0, "Pari", "Dispari") -> Pari
A35: price | B35: esplicita il data type della colonna | C35: =IF(Completeness!C21=1, "Sì", "No") -> Sì | D35: 0 | E35: menziona il data type della colonna (B21) | J35: =IF(MOD(ROW(), 2)=0, "Pari", "Dispari") -> Dispari
A36: price | B36: esplicita il valore minimo oppure fornisce il codice | C36: =IF(Completeness!C23=1, "Sì", "No") -> Sì | D36: 1 | E36: menziona il minimo del range dei valori (B23) | J36: =IF(MOD(ROW(), 2)=0, "Pari", "Dispari") -> Pari
A37: price | B37: esplicita il valore minimo | C37: =IF(Completeness!C23=1, "Sì", "No") -> Sì | D37: 0 | E37: menziona il minimo del range dei valori (B23) | J37: =IF(MOD(ROW(), 2)=0, "Pari", "Dispari") -> Dispari
A38: price | B38: esplicita il val massimo oppure fornisce il codice | C38: =IF(Completeness!C24=1, "Sì", "No") -> Sì | D38: 1 | E38: menziona il massimo del range dei valori (B24) | J38: =IF(MOD(ROW(), 2)=0, "Pari", "Dispari") -> Pari
A39: price | B39: esplicita il val massimo | C39: =IF(Completeness!C24=1, "Sì", "No") -> Sì | D39: 0 | E39: menziona il massimo del range dei valori (B24) | J39: =IF(MOD(ROW(), 2)=0, "Pari", "Dispari") -> Dispari
A40: price | B40: esplicita la media del range dei valori oppure fornisce il codice | C40: =IF(Completeness!C25=1, "Sì", "No") -> Sì | D40: 1 | E40: menziona la media del range dei valori (B25) | J40: =IF(MOD(ROW(), 2)=0, "Pari", "Dispari") -> Pari
...

Sheet Flag
A1: hallucination flag
A3: l'LLM allucina | B3: No
